INFO 2018-04-19 14:18:40,841 views.py views login_handle 56: 请输入正确的用户名和密码！
INFO 2018-04-19 14:18:50,140 views.py views login_handle 53: [gonglp] 登录成功
INFO 2018-04-19 14:22:43,932 views.py views login_handle 53: [gonglp] 登录成功
INFO 2018-04-19 14:27:10,751 views.py views login_handle 53: [gonglp] 登录成功
INFO 2018-04-19 14:35:18,838 views.py views login_handle 53: [gonglp] 登录成功
INFO 2018-04-19 14:46:02,971 views.py views login_handle 53: [gonglp] 登录成功
INFO 2018-04-19 15:06:35,567 views.py views login_handle 53: [gonglp] 登录成功
INFO 2018-04-19 15:09:25,360 views.py views login_handle 53: [gonglp] 登录成功
INFO 2018-04-19 15:13:22,409 views.py views login_handle 53: [gonglp] 登录成功
INFO 2018-04-19 15:16:06,003 views.py views login_handle 53: [gonglp] 登录成功
INFO 2018-04-19 15:32:17,463 views.py views login_handle 53: [gonglp] 登录成功
INFO 2018-04-19 16:01:23,965 views.py views login_handle 53: [gonglp] 登录成功
INFO 2018-04-19 16:05:31,894 views.py views login_handle 53: [gonglp] 登录成功
INFO 2018-04-19 16:08:50,010 views.py views login_handle 53: [gonglp] 登录成功
INFO 2018-04-19 16:20:58,137 views.py views login_handle 53: [gonglp] 登录成功
INFO 2018-04-19 16:29:08,737 views.py views login_handle 53: [gonglp] 登录成功
INFO 2018-04-19 17:54:31,945 views.py views login_handle 53: [gonglp] 登录成功
INFO 2018-04-19 17:55:12,977 views.py views login_handle 53: [liud] 登录成功
INFO 2018-04-19 17:58:26,764 views.py views project_manage 87: 进入项目中心-->项目管理页面
INFO 2018-04-19 17:58:26,816 views.py views project_manage 87: 进入项目中心-->项目管理页面
INFO 2018-04-19 17:58:27,005 views.py views Read_all_project 106: 查询所有项目
INFO 2018-04-19 17:58:27,138 views.py views Read_all_project 106: 查询所有项目
INFO 2018-04-19 18:01:16,411 views.py views login_handle 53: [gonglp] 登录成功
INFO 2018-04-19 18:15:59,389 views.py views login_handle 53: [gonglp] 登录成功
INFO 2018-04-20 09:09:30,302 views.py views login_handle 53: [gonglp] 登录成功
INFO 2018-04-20 09:10:09,232 views.py views login_handle 53: [luoyh] 登录成功
INFO 2018-04-20 09:10:29,918 views.py views login_handle 53: [gonglp] 登录成功
INFO 2018-04-20 09:33:46,847 views.py views login_handle 53: [gonglp] 登录成功
INFO 2018-04-20 09:36:11,053 views.py views login_handle 53: [gonglp] 登录成功
INFO 2018-04-20 09:36:51,717 views.py views login_handle 53: [gonglp] 登录成功
INFO 2018-04-20 09:37:29,230 views.py views login_handle 53: [gonglp] 登录成功
INFO 2018-04-20 09:38:33,675 views.py views login_handle 53: [gonglp] 登录成功
INFO 2018-04-20 09:39:14,085 views.py views login_handle 53: [gonglp] 登录成功
ERROR 2018-04-20 09:45:56,384 views.py views execute_test_script 1282: 存储用户Session-2018_4_13_11_19_52.py:FAILED: error message [ 未获取脚本执行状态，脚本执行失败 ] Traceback (most recent call last):
  File "/home/fzyzgong/project/AutoFWOG/AutoFW/script/genirtor_script/存储用户Session-2018_4_13_11_19_52.py", line 19, in testDemo
    r = requests.put(self.protocol + domian + url, json=param, timeout=8)
  File "/home/fzyzgong/.virtualenvs/AutoFW/local/lib/python2.7/site-packages/requests/api.py", line 126, in put
    return request('put', url, data=data, **kwargs)
  File "/home/fzyzgong/.virtualenvs/AutoFW/local/lib/python2.7/site-packages/requests/api.py", line 58, in request
    return session.request(method=method, url=url, **kwargs)
  File "/home/fzyzgong/.virtualenvs/AutoFW/local/lib/python2.7/site-packages/requests/sessions.py", line 508, in request
    resp = self.send(prep, **send_kwargs)
  File "/home/fzyzgong/.virtualenvs/AutoFW/local/lib/python2.7/site-packages/requests/sessions.py", line 618, in send
    r = adapter.send(request, **kwargs)
  File "/home/fzyzgong/.virtualenvs/AutoFW/local/lib/python2.7/site-packages/requests/adapters.py", line 508, in send
    raise ConnectionError(e, request=request)
ConnectionError: HTTPSConnectionPool(host='ta1.2boss.cn', port=443): Max retries exceeded with url: /ubt/api/session (Caused by NewConnectionError('<urllib3.connection.VerifiedHTTPSConnection object at 0x7f36e461bb50>: Failed to establish a new connection: [Errno -5] No address associated with hostname',))


INFO 2018-04-20 09:45:57,441 views.py views execute_test_script 1244: 实时获取tab标签发现（信息）-2018_4_13_11_19_52.py:PASS:[time_consuming:0.346089]{ response : 'resultCode: 0' }
ERROR 2018-04-20 09:45:57,835 views.py views execute_test_script 1282: 平台框架获取事件列表-2018_4_13_11_19_52.py:FAILED: error message [ 未获取脚本执行状态，脚本执行失败 ] Traceback (most recent call last):
  File "/home/fzyzgong/project/AutoFWOG/AutoFW/script/genirtor_script/平台框架获取事件列表-2018_4_13_11_19_52.py", line 21, in testDemo
    r = requests.get(self.protocol + domian  + url,headers=headers, params=param, timeout=8)
  File "/home/fzyzgong/.virtualenvs/AutoFW/local/lib/python2.7/site-packages/requests/api.py", line 72, in get
    return request('get', url, params=params, **kwargs)
  File "/home/fzyzgong/.virtualenvs/AutoFW/local/lib/python2.7/site-packages/requests/api.py", line 58, in request
    return session.request(method=method, url=url, **kwargs)
  File "/home/fzyzgong/.virtualenvs/AutoFW/local/lib/python2.7/site-packages/requests/sessions.py", line 494, in request
    prep = self.prepare_request(req)
  File "/home/fzyzgong/.virtualenvs/AutoFW/local/lib/python2.7/site-packages/requests/sessions.py", line 437, in prepare_request
    hooks=merge_hooks(request.hooks, self.hooks),
  File "/home/fzyzgong/.virtualenvs/AutoFW/local/lib/python2.7/site-packages/requests/models.py", line 306, in prepare
    self.prepare_headers(headers)
  File "/home/fzyzgong/.virtualenvs/AutoFW/local/lib/python2.7/site-packages/requests/models.py", line 438, in prepare_headers
    for header in headers.items():
AttributeError: 'str' object has no attribute 'items'


INFO 2018-04-20 09:53:30,821 views.py views login_handle 53: [gonglp] 登录成功
INFO 2018-04-20 09:54:50,174 views.py views login_handle 53: [gonglp] 登录成功
INFO 2018-04-20 09:56:40,178 views.py views login_handle 53: [gonglp] 登录成功
INFO 2018-04-20 10:17:38,867 views.py views login_handle 53: [gonglp] 登录成功
ERROR 2018-04-20 10:18:34,839 views.py views execute_test_script 1283: 存储用户Session-2018_4_13_11_19_52.py:FAILED: error message [ 未获取脚本执行状态，脚本执行失败 ] Traceback (most recent call last):
  File "/home/fzyzgong/project/AutoFWOG/AutoFW/script/genirtor_script/存储用户Session-2018_4_13_11_19_52.py", line 19, in testDemo
    r = requests.put(self.protocol + domian + url, json=param, timeout=8)
  File "/home/fzyzgong/.virtualenvs/AutoFW/local/lib/python2.7/site-packages/requests/api.py", line 126, in put
    return request('put', url, data=data, **kwargs)
  File "/home/fzyzgong/.virtualenvs/AutoFW/local/lib/python2.7/site-packages/requests/api.py", line 58, in request
    return session.request(method=method, url=url, **kwargs)
  File "/home/fzyzgong/.virtualenvs/AutoFW/local/lib/python2.7/site-packages/requests/sessions.py", line 508, in request
    resp = self.send(prep, **send_kwargs)
  File "/home/fzyzgong/.virtualenvs/AutoFW/local/lib/python2.7/site-packages/requests/sessions.py", line 618, in send
    r = adapter.send(request, **kwargs)
  File "/home/fzyzgong/.virtualenvs/AutoFW/local/lib/python2.7/site-packages/requests/adapters.py", line 508, in send
    raise ConnectionError(e, request=request)
ConnectionError: HTTPSConnectionPool(host='ta1.2boss.cn', port=443): Max retries exceeded with url: /ubt/api/session (Caused by NewConnectionError('<urllib3.connection.VerifiedHTTPSConnection object at 0x7fcfcf1ddb50>: Failed to establish a new connection: [Errno -5] No address associated with hostname',))


INFO 2018-04-20 10:18:36,082 views.py views execute_test_script 1245: 实时获取tab标签发现（信息）-2018_4_13_11_19_52.py:PASS:[time_consuming:0.43436]{ response : 'resultCode: 0' }
ERROR 2018-04-20 10:18:36,506 views.py views execute_test_script 1283: 平台框架获取事件列表-2018_4_13_11_19_52.py:FAILED: error message [ 未获取脚本执行状态，脚本执行失败 ] Traceback (most recent call last):
  File "/home/fzyzgong/project/AutoFWOG/AutoFW/script/genirtor_script/平台框架获取事件列表-2018_4_13_11_19_52.py", line 21, in testDemo
    r = requests.get(self.protocol + domian  + url,headers=headers, params=param, timeout=8)
  File "/home/fzyzgong/.virtualenvs/AutoFW/local/lib/python2.7/site-packages/requests/api.py", line 72, in get
    return request('get', url, params=params, **kwargs)
  File "/home/fzyzgong/.virtualenvs/AutoFW/local/lib/python2.7/site-packages/requests/api.py", line 58, in request
    return session.request(method=method, url=url, **kwargs)
  File "/home/fzyzgong/.virtualenvs/AutoFW/local/lib/python2.7/site-packages/requests/sessions.py", line 494, in request
    prep = self.prepare_request(req)
  File "/home/fzyzgong/.virtualenvs/AutoFW/local/lib/python2.7/site-packages/requests/sessions.py", line 437, in prepare_request
    hooks=merge_hooks(request.hooks, self.hooks),
  File "/home/fzyzgong/.virtualenvs/AutoFW/local/lib/python2.7/site-packages/requests/models.py", line 306, in prepare
    self.prepare_headers(headers)
  File "/home/fzyzgong/.virtualenvs/AutoFW/local/lib/python2.7/site-packages/requests/models.py", line 438, in prepare_headers
    for header in headers.items():
AttributeError: 'str' object has no attribute 'items'


INFO 2018-04-20 10:20:24,978 views.py views login_handle 53: [gonglp] 登录成功
INFO 2018-04-20 10:33:09,031 views.py views login_handle 53: [lerj] 登录成功
ERROR 2018-04-20 10:33:46,593 views.py views execute_test_script 1258: 更新绑定用户信息-2018_4_13_11_19_52.py:FAILED: error message [', "{u'status': 404, u'timestamp': 1524191626469, u'message': u'No message available', u'path': u'/superior/v1/im/imUpdateCustomer12', u'error': u'Not Found'}")
]
ERROR 2018-04-20 10:33:47,159 views.py views execute_test_script 1283: 检查版本信息-2018_4_13_11_19_52.py:FAILED: error message [ 未获取脚本执行状态，脚本执行失败 ] Traceback (most recent call last):
  File "/home/fzyzgong/project/AutoFWOG/AutoFW/script/genirtor_script/检查版本信息-2018_4_13_11_19_52.py", line 17, in testDemo
    r = requests.post(self.protocol + domian + url, headers=headers, timeout=8)
  File "/home/fzyzgong/.virtualenvs/AutoFW/local/lib/python2.7/site-packages/requests/api.py", line 112, in post
    return request('post', url, data=data, json=json, **kwargs)
  File "/home/fzyzgong/.virtualenvs/AutoFW/local/lib/python2.7/site-packages/requests/api.py", line 58, in request
    return session.request(method=method, url=url, **kwargs)
  File "/home/fzyzgong/.virtualenvs/AutoFW/local/lib/python2.7/site-packages/requests/sessions.py", line 494, in request
    prep = self.prepare_request(req)
  File "/home/fzyzgong/.virtualenvs/AutoFW/local/lib/python2.7/site-packages/requests/sessions.py", line 437, in prepare_request
    hooks=merge_hooks(request.hooks, self.hooks),
  File "/home/fzyzgong/.virtualenvs/AutoFW/local/lib/python2.7/site-packages/requests/models.py", line 306, in prepare
    self.prepare_headers(headers)
  File "/home/fzyzgong/.virtualenvs/AutoFW/local/lib/python2.7/site-packages/requests/models.py", line 440, in prepare_headers
    check_header_validity(header)
  File "/home/fzyzgong/.virtualenvs/AutoFW/local/lib/python2.7/site-packages/requests/utils.py", line 872, in check_header_validity
    "bytes, not %s" % (name, value, type(value)))
InvalidHeader: Value for header {appId: 1} must be of type str or bytes, not <type 'int'>


INFO 2018-04-20 10:33:47,822 views.py views execute_test_script 1245: 登录初始化-2018_4_13_11_19_52.py:PASS:[time_consuming:0.205222]{ response : 'resultCode: 0' }
ERROR 2018-04-20 10:44:12,706 views.py views execute_test_script 1258: 更新绑定用户信息-2018_4_13_11_19_52.py:FAILED: error message [', "{u'status': 404, u'timestamp': 1524192252606, u'message': u'No message available', u'path': u'/superior/v1/im/imUpdateCustomer12', u'error': u'Not Found'}")
]
ERROR 2018-04-20 10:44:52,120 views.py views execute_test_script 1258: 更新绑定用户信息-2018_4_13_11_19_52.py:FAILED: error message [', "{u'status': 404, u'timestamp': 1524192292021, u'message': u'No message available', u'path': u'/superior/v1/im/imUpdateCustomer12', u'error': u'Not Found'}")
]
INFO 2018-04-20 10:45:34,020 views.py views login_handle 53: [lerj] 登录成功
INFO 2018-04-20 10:45:50,057 views.py views login_handle 53: [gonglp] 登录成功
INFO 2018-04-20 10:46:02,268 views.py views login_handle 53: [lerj] 登录成功
ERROR 2018-04-20 10:46:33,593 views.py views execute_test_script 1258: 更新绑定用户信息-2018_4_13_11_19_52.py:FAILED: error message [', "{u'status': 404, u'timestamp': 1524192393496, u'message': u'No message available', u'path': u'/superior/v1/im/imUpdateCustomer12', u'error': u'Not Found'}")
]
ERROR 2018-04-20 10:48:13,842 views.py views execute_test_script 1258: 更新绑定用户信息-2018_4_13_11_19_52.py:FAILED: error message [', "{u'status': 404, u'timestamp': 1524192493743, u'message': u'No message available', u'path': u'/superior/v1/im/imUpdateCustomer12', u'error': u'Not Found'}")
]
INFO 2018-04-20 11:21:21,644 views.py views login_handle 53: [lerj] 登录成功
ERROR 2018-04-20 11:21:57,605 views.py views execute_test_script 1258: 更新绑定用户信息-2018_4_13_11_19_52.py:FAILED: error message [', "{u'status': 404, u'timestamp': 1524194517404, u'message': u'No message available', u'path': u'/superior/v1/im/imUpdateCustomer12', u'error': u'Not Found'}")
]
ERROR 2018-04-20 11:26:50,255 views.py views execute_test_script 1258: 更新绑定用户信息-2018_4_13_11_19_52.py:FAILED: error message [', "{u'status': 404, u'timestamp': 1524194809923, u'message': u'No message available', u'path': u'/superior/v1/im/imUpdateCustomer12', u'error': u'Not Found'}")
]
INFO 2018-04-20 11:29:29,360 views.py views login_handle 53: [lerj] 登录成功
ERROR 2018-04-20 11:30:04,652 views.py views execute_test_script 1283: 检查版本信息-2018_4_13_11_19_52.py:FAILED: error message [ 未获取脚本执行状态，脚本执行失败 ] Traceback (most recent call last):
  File "/home/fzyzgong/project/AutoFWOG/AutoFW/script/genirtor_script/检查版本信息-2018_4_13_11_19_52.py", line 17, in testDemo
    r = requests.post(self.protocol + domian + url, headers=headers, timeout=8)
  File "/home/fzyzgong/.virtualenvs/AutoFW/local/lib/python2.7/site-packages/requests/api.py", line 112, in post
    return request('post', url, data=data, json=json, **kwargs)
  File "/home/fzyzgong/.virtualenvs/AutoFW/local/lib/python2.7/site-packages/requests/api.py", line 58, in request
    return session.request(method=method, url=url, **kwargs)
  File "/home/fzyzgong/.virtualenvs/AutoFW/local/lib/python2.7/site-packages/requests/sessions.py", line 494, in request
    prep = self.prepare_request(req)
  File "/home/fzyzgong/.virtualenvs/AutoFW/local/lib/python2.7/site-packages/requests/sessions.py", line 437, in prepare_request
    hooks=merge_hooks(request.hooks, self.hooks),
  File "/home/fzyzgong/.virtualenvs/AutoFW/local/lib/python2.7/site-packages/requests/models.py", line 306, in prepare
    self.prepare_headers(headers)
  File "/home/fzyzgong/.virtualenvs/AutoFW/local/lib/python2.7/site-packages/requests/models.py", line 440, in prepare_headers
    check_header_validity(header)
  File "/home/fzyzgong/.virtualenvs/AutoFW/local/lib/python2.7/site-packages/requests/utils.py", line 872, in check_header_validity
    "bytes, not %s" % (name, value, type(value)))
InvalidHeader: Value for header {appId: 1} must be of type str or bytes, not <type 'int'>


INFO 2018-04-20 11:39:45,802 views.py views login_handle 53: [lerj] 登录成功
ERROR 2018-04-20 11:40:19,102 views.py views execute_test_script 1277: 检查版本信息-2018_4_13_11_19_52.py:FAILED: error message [ 未获取脚本执行状态，脚本执行失败 ] Traceback (most recent call last):
  File "/home/fzyzgong/project/AutoFWOG/AutoFW/script/genirtor_script/检查版本信息-2018_4_13_11_19_52.py", line 17, in testDemo
    r = requests.post(self.protocol + domian + url, headers=headers, timeout=8)
  File "/home/fzyzgong/.virtualenvs/AutoFW/local/lib/python2.7/site-packages/requests/api.py", line 112, in post
    return request('post', url, data=data, json=json, **kwargs)
  File "/home/fzyzgong/.virtualenvs/AutoFW/local/lib/python2.7/site-packages/requests/api.py", line 58, in request
    return session.request(method=method, url=url, **kwargs)
  File "/home/fzyzgong/.virtualenvs/AutoFW/local/lib/python2.7/site-packages/requests/sessions.py", line 494, in request
    prep = self.prepare_request(req)
  File "/home/fzyzgong/.virtualenvs/AutoFW/local/lib/python2.7/site-packages/requests/sessions.py", line 437, in prepare_request
    hooks=merge_hooks(request.hooks, self.hooks),
  File "/home/fzyzgong/.virtualenvs/AutoFW/local/lib/python2.7/site-packages/requests/models.py", line 306, in prepare
    self.prepare_headers(headers)
  File "/home/fzyzgong/.virtualenvs/AutoFW/local/lib/python2.7/site-packages/requests/models.py", line 440, in prepare_headers
    check_header_validity(header)
  File "/home/fzyzgong/.virtualenvs/AutoFW/local/lib/python2.7/site-packages/requests/utils.py", line 872, in check_header_validity
    "bytes, not %s" % (name, value, type(value)))
InvalidHeader: Value for header {appId: 1} must be of type str or bytes, not <type 'int'>


ERROR 2018-04-20 11:41:22,545 views.py views execute_test_script 1277: 检查版本信息-2018_4_13_11_19_52.py:FAILED: error message [ 未获取脚本执行状态，脚本执行失败 ] Traceback (most recent call last):
  File "/home/fzyzgong/project/AutoFWOG/AutoFW/script/genirtor_script/检查版本信息-2018_4_13_11_19_52.py", line 17, in testDemo
    r = requests.post(self.protocol + domian + url, headers=headers, timeout=8)
  File "/home/fzyzgong/.virtualenvs/AutoFW/local/lib/python2.7/site-packages/requests/api.py", line 112, in post
    return request('post', url, data=data, json=json, **kwargs)
  File "/home/fzyzgong/.virtualenvs/AutoFW/local/lib/python2.7/site-packages/requests/api.py", line 58, in request
    return session.request(method=method, url=url, **kwargs)
  File "/home/fzyzgong/.virtualenvs/AutoFW/local/lib/python2.7/site-packages/requests/sessions.py", line 494, in request
    prep = self.prepare_request(req)
  File "/home/fzyzgong/.virtualenvs/AutoFW/local/lib/python2.7/site-packages/requests/sessions.py", line 437, in prepare_request
    hooks=merge_hooks(request.hooks, self.hooks),
  File "/home/fzyzgong/.virtualenvs/AutoFW/local/lib/python2.7/site-packages/requests/models.py", line 306, in prepare
    self.prepare_headers(headers)
  File "/home/fzyzgong/.virtualenvs/AutoFW/local/lib/python2.7/site-packages/requests/models.py", line 440, in prepare_headers
    check_header_validity(header)
  File "/home/fzyzgong/.virtualenvs/AutoFW/local/lib/python2.7/site-packages/requests/utils.py", line 872, in check_header_validity
    "bytes, not %s" % (name, value, type(value)))
InvalidHeader: Value for header {appId: 1} must be of type str or bytes, not <type 'int'>


INFO 2018-04-20 13:28:36,509 views.py views project_manage 87: 进入项目中心-->项目管理页面
INFO 2018-04-20 13:28:36,560 views.py views project_manage 87: 进入项目中心-->项目管理页面
INFO 2018-04-20 13:28:36,757 views.py views Read_all_project 106: 查询所有项目
INFO 2018-04-20 13:28:36,867 views.py views Read_all_project 106: 查询所有项目
INFO 2018-04-20 13:28:39,030 views.py views income_project 142: lerj进入项目[20171021]
INFO 2018-04-20 13:29:05,277 views.py views project_manage 87: 进入项目中心-->项目管理页面
INFO 2018-04-20 13:29:05,375 views.py views Read_all_project 106: 查询所有项目
INFO 2018-04-20 13:29:16,922 views.py views project_manage 87: 进入项目中心-->项目管理页面
INFO 2018-04-20 13:29:16,935 views.py views project_manage 87: 进入项目中心-->项目管理页面
INFO 2018-04-20 13:29:17,043 views.py views Read_all_project 106: 查询所有项目
INFO 2018-04-20 13:29:17,198 views.py views Read_all_project 106: 查询所有项目
INFO 2018-04-20 13:29:36,989 views.py views income_project 142: lerj进入项目[20171022]
INFO 2018-04-20 13:29:41,876 views.py views project_manage 87: 进入项目中心-->项目管理页面
INFO 2018-04-20 13:29:41,970 views.py views Read_all_project 106: 查询所有项目
INFO 2018-04-20 13:29:58,359 views.py views project_manage 87: 进入项目中心-->项目管理页面
INFO 2018-04-20 13:29:58,368 views.py views project_manage 87: 进入项目中心-->项目管理页面
INFO 2018-04-20 13:29:58,483 views.py views Read_all_project 106: 查询所有项目
INFO 2018-04-20 13:29:58,635 views.py views Read_all_project 106: 查询所有项目
INFO 2018-04-20 13:30:04,523 views.py views income_project 142: lerj进入项目[TBS_USER_20180328]
INFO 2018-04-20 13:30:13,250 views.py views workon_tabs_api 386: lerj进入接口管理页面 [TBS_USER_20180328]
INFO 2018-04-20 13:30:15,196 views.py views income_project 142: 进入项目[TBS_USER_20180328]
INFO 2018-04-20 13:30:25,686 views.py views project_manage 87: 进入项目中心-->项目管理页面
INFO 2018-04-20 13:30:25,694 views.py views project_manage 87: 进入项目中心-->项目管理页面
INFO 2018-04-20 13:30:25,826 views.py views Read_all_project 106: 查询所有项目
INFO 2018-04-20 13:30:32,645 views.py views income_project 142: lerj进入项目[TBS_USER_20180328]
INFO 2018-04-20 13:30:36,570 views.py views workon_tabs_api 386: lerj进入接口管理页面 [TBS_USER_20180328]
INFO 2018-04-20 13:42:41,774 views.py views login_handle 53: [lerj] 登录成功
INFO 2018-04-20 13:43:00,290 views.py views login_handle 53: [lerj] 登录成功
INFO 2018-04-20 13:43:14,259 views.py views login_handle 53: [lerj] 登录成功
INFO 2018-04-20 13:43:36,524 views.py views login_handle 53: [lerj] 登录成功
INFO 2018-04-20 13:46:40,482 views.py views login_handle 53: [lerj] 登录成功
INFO 2018-04-20 13:48:52,551 views.py views login_handle 53: [lerj] 登录成功
INFO 2018-04-20 13:54:12,573 views.py views login_handle 53: [lerj] 登录成功
INFO 2018-04-20 13:54:23,983 views.py views project_manage 87: 进入项目中心-->项目管理页面
INFO 2018-04-20 13:54:23,991 views.py views project_manage 87: 进入项目中心-->项目管理页面
INFO 2018-04-20 13:54:24,520 views.py views Read_all_project 106: 查询所有项目
INFO 2018-04-20 13:57:06,146 views.py views login_handle 53: [lerj] 登录成功
INFO 2018-04-20 14:00:03,851 views.py views login_handle 53: [lerj] 登录成功
ERROR 2018-04-20 14:01:37,615 views.py views execute_test_script 1277: 检查版本信息-2018_4_13_11_19_52.py:FAILED: error message [ 未获取脚本执行状态，脚本执行失败 ] Traceback (most recent call last):
  File "/home/fzyzgong/project/AutoFWOG/AutoFW/script/genirtor_script/检查版本信息-2018_4_13_11_19_52.py", line 17, in testDemo
    r = requests.post(self.protocol + domian + url, headers=headers, timeout=8)
  File "/home/fzyzgong/.virtualenvs/AutoFW/local/lib/python2.7/site-packages/requests/api.py", line 112, in post
    return request('post', url, data=data, json=json, **kwargs)
  File "/home/fzyzgong/.virtualenvs/AutoFW/local/lib/python2.7/site-packages/requests/api.py", line 58, in request
    return session.request(method=method, url=url, **kwargs)
  File "/home/fzyzgong/.virtualenvs/AutoFW/local/lib/python2.7/site-packages/requests/sessions.py", line 494, in request
    prep = self.prepare_request(req)
  File "/home/fzyzgong/.virtualenvs/AutoFW/local/lib/python2.7/site-packages/requests/sessions.py", line 437, in prepare_request
    hooks=merge_hooks(request.hooks, self.hooks),
  File "/home/fzyzgong/.virtualenvs/AutoFW/local/lib/python2.7/site-packages/requests/models.py", line 306, in prepare
    self.prepare_headers(headers)
  File "/home/fzyzgong/.virtualenvs/AutoFW/local/lib/python2.7/site-packages/requests/models.py", line 440, in prepare_headers
    check_header_validity(header)
  File "/home/fzyzgong/.virtualenvs/AutoFW/local/lib/python2.7/site-packages/requests/utils.py", line 872, in check_header_validity
    "bytes, not %s" % (name, value, type(value)))
InvalidHeader: Value for header {appId: 1} must be of type str or bytes, not <type 'int'>


INFO 2018-04-20 14:04:50,019 views.py views execute_test_script 1245: 登录初始化-2018_4_13_11_19_52.py:PASS:[time_consuming:0.20471]{ response : 'resultCode: 0' }
INFO 2018-04-20 14:10:38,304 views.py views execute_test_script 1245: 登录初始化-2018_4_13_11_19_52.py:PASS:[time_consuming:0.163238]{ response : 'resultCode: 0' }
INFO 2018-04-20 14:13:31,457 views.py views login_handle 53: [lerj] 登录成功
INFO 2018-04-20 14:13:51,406 views.py views execute_test_script 1245: 登录初始化-2018_4_13_11_19_52.py:PASS:[time_consuming:0.123816]{ response : 'resultCode: 0' }
INFO 2018-04-20 14:16:50,559 views.py views login_handle 53: [lerj] 登录成功
INFO 2018-04-20 14:17:18,112 views.py views execute_test_script 1245: 登录初始化-2018_4_13_11_19_52.py:PASS:[time_consuming:0.0686]{ response : 'resultCode: 0' }
INFO 2018-04-20 14:21:22,558 views.py views execute_test_script 1245: 实时获取tab标签发现（信息）-2018_4_13_11_19_52.py:PASS:[time_consuming:0.414741]{ response : 'resultCode: 0' }
ERROR 2018-04-20 14:21:23,576 views.py views execute_test_script 1277: 平台框架获取事件列表-2018_4_13_11_19_52.py:FAILED: error message [ 未获取脚本执行状态，脚本执行失败 ] Traceback (most recent call last):
  File "/home/fzyzgong/project/AutoFWOG/AutoFW/script/genirtor_script/平台框架获取事件列表-2018_4_13_11_19_52.py", line 21, in testDemo
    r = requests.get(self.protocol + domian  + url,headers=headers, params=param, timeout=8)
  File "/home/fzyzgong/.virtualenvs/AutoFW/local/lib/python2.7/site-packages/requests/api.py", line 72, in get
    return request('get', url, params=params, **kwargs)
  File "/home/fzyzgong/.virtualenvs/AutoFW/local/lib/python2.7/site-packages/requests/api.py", line 58, in request
    return session.request(method=method, url=url, **kwargs)
  File "/home/fzyzgong/.virtualenvs/AutoFW/local/lib/python2.7/site-packages/requests/sessions.py", line 494, in request
    prep = self.prepare_request(req)
  File "/home/fzyzgong/.virtualenvs/AutoFW/local/lib/python2.7/site-packages/requests/sessions.py", line 437, in prepare_request
    hooks=merge_hooks(request.hooks, self.hooks),
  File "/home/fzyzgong/.virtualenvs/AutoFW/local/lib/python2.7/site-packages/requests/models.py", line 306, in prepare
    self.prepare_headers(headers)
  File "/home/fzyzgong/.virtualenvs/AutoFW/local/lib/python2.7/site-packages/requests/models.py", line 438, in prepare_headers
    for header in headers.items():
AttributeError: 'str' object has no attribute 'items'


INFO 2018-04-20 14:24:18,554 views.py views login_handle 53: [gonglp] 登录成功
INFO 2018-04-20 14:24:36,218 views.py views execute_test_script 1245: 实时获取tab标签发现（信息）-2018_4_13_11_19_52.py:PASS:[time_consuming:0.377444]{ response : 'resultCode: 0' }
ERROR 2018-04-20 14:24:37,725 views.py views execute_test_script 1277: 平台框架获取事件列表-2018_4_13_11_19_52.py:FAILED: error message [ 未获取脚本执行状态，脚本执行失败 ] Traceback (most recent call last):
  File "/home/fzyzgong/project/AutoFWOG/AutoFW/script/genirtor_script/平台框架获取事件列表-2018_4_13_11_19_52.py", line 21, in testDemo
    r = requests.get(self.protocol + domian  + url,headers=headers, params=param, timeout=8)
  File "/home/fzyzgong/.virtualenvs/AutoFW/local/lib/python2.7/site-packages/requests/api.py", line 72, in get
    return request('get', url, params=params, **kwargs)
  File "/home/fzyzgong/.virtualenvs/AutoFW/local/lib/python2.7/site-packages/requests/api.py", line 58, in request
    return session.request(method=method, url=url, **kwargs)
  File "/home/fzyzgong/.virtualenvs/AutoFW/local/lib/python2.7/site-packages/requests/sessions.py", line 494, in request
    prep = self.prepare_request(req)
  File "/home/fzyzgong/.virtualenvs/AutoFW/local/lib/python2.7/site-packages/requests/sessions.py", line 437, in prepare_request
    hooks=merge_hooks(request.hooks, self.hooks),
  File "/home/fzyzgong/.virtualenvs/AutoFW/local/lib/python2.7/site-packages/requests/models.py", line 306, in prepare
    self.prepare_headers(headers)
  File "/home/fzyzgong/.virtualenvs/AutoFW/local/lib/python2.7/site-packages/requests/models.py", line 438, in prepare_headers
    for header in headers.items():
AttributeError: 'str' object has no attribute 'items'


INFO 2018-04-20 14:26:42,260 views.py views execute_test_script 1245: 实时获取tab标签发现（信息）-2018_4_13_11_19_52.py:PASS:[time_consuming:0.346707]{ response : 'resultCode: 0' }
ERROR 2018-04-20 14:26:42,847 views.py views execute_test_script 1277: 平台框架获取事件列表-2018_4_13_11_19_52.py:FAILED: error message [ 未获取脚本执行状态，脚本执行失败 ] Traceback (most recent call last):
  File "/home/fzyzgong/project/AutoFWOG/AutoFW/script/genirtor_script/平台框架获取事件列表-2018_4_13_11_19_52.py", line 21, in testDemo
    r = requests.get(self.protocol + domian  + url,headers=headers, params=param, timeout=8)
  File "/home/fzyzgong/.virtualenvs/AutoFW/local/lib/python2.7/site-packages/requests/api.py", line 72, in get
    return request('get', url, params=params, **kwargs)
  File "/home/fzyzgong/.virtualenvs/AutoFW/local/lib/python2.7/site-packages/requests/api.py", line 58, in request
    return session.request(method=method, url=url, **kwargs)
  File "/home/fzyzgong/.virtualenvs/AutoFW/local/lib/python2.7/site-packages/requests/sessions.py", line 494, in request
    prep = self.prepare_request(req)
  File "/home/fzyzgong/.virtualenvs/AutoFW/local/lib/python2.7/site-packages/requests/sessions.py", line 437, in prepare_request
    hooks=merge_hooks(request.hooks, self.hooks),
  File "/home/fzyzgong/.virtualenvs/AutoFW/local/lib/python2.7/site-packages/requests/models.py", line 306, in prepare
    self.prepare_headers(headers)
  File "/home/fzyzgong/.virtualenvs/AutoFW/local/lib/python2.7/site-packages/requests/models.py", line 438, in prepare_headers
    for header in headers.items():
AttributeError: 'str' object has no attribute 'items'


INFO 2018-04-20 14:32:42,621 views.py views login_handle 53: [gonglp] 登录成功
INFO 2018-04-20 14:32:57,624 views.py views execute_test_script 1245: 登录初始化-2018_4_13_11_19_52.py:PASS:[time_consuming:0.096532]{ response : 'resultCode: 0' }
INFO 2018-04-20 15:06:29,852 views.py views login_handle 53: [gonglp] 登录成功
INFO 2018-04-20 15:08:13,981 views.py views login_handle 53: [gonglp] 登录成功
INFO 2018-04-20 15:09:35,826 views.py views login_handle 53: [gonglp] 登录成功
INFO 2018-04-20 15:11:45,081 views.py views login_handle 53: [gonglp] 登录成功
INFO 2018-04-20 15:15:55,036 views.py views login_handle 53: [gonglp] 登录成功
INFO 2018-04-20 15:45:10,566 views.py views login_handle 53: [gonglp] 登录成功
INFO 2018-04-20 16:23:27,170 views.py views login_handle 53: [gonglp] 登录成功
INFO 2018-04-20 16:26:09,662 views.py views login_handle 56: 请输入正确的用户名和密码！
INFO 2018-04-20 16:26:18,132 views.py views login_handle 53: [gonglp] 登录成功
INFO 2018-04-20 18:13:00,839 views.py views login_handle 53: [gonglp] 登录成功
INFO 2018-04-20 18:23:22,796 views.py views login_handle 53: [gonglp] 登录成功
INFO 2018-04-20 18:35:27,850 views.py views execute_test_script 1245: 存储用户Session-2018_4_20_18_23_32.py:PASS:[time_consuming:0.139682]{ response : 'resultCode: 0' }
INFO 2018-04-20 18:35:28,540 views.py views execute_test_script 1245: 实时获取tab标签发现（信息）-2018_4_20_18_23_32.py:PASS:[time_consuming:0.20159]{ response : 'resultCode: 0' }
INFO 2018-04-20 18:35:28,885 views.py views execute_test_script 1245: 平台框架获取事件列表-2018_4_20_18_23_32.py:PASS:[time_consuming:0.059206]{ response : 'resultCode: 0' }
INFO 2018-04-20 18:35:29,198 views.py views execute_test_script 1245: 更新绑定用户信息-2018_4_20_18_23_32.py:PASS:[time_consuming:0.073159]{ response : 'resultCode: 0' }
ERROR 2018-04-20 18:35:29,474 views.py views execute_test_script 1277: 检查版本信息-2018_4_20_18_23_31.py:FAILED: error message [ 未获取脚本执行状态，脚本执行失败 ] Traceback (most recent call last):
  File "/home/fzyzgong/project/AutoFWOG/AutoFW/script/genirtor_script/检查版本信息-2018_4_20_18_23_31.py", line 17, in testDemo
    r = requests.post(self.protocol + domian + url, headers=headers, timeout=8)
  File "/home/fzyzgong/.virtualenvs/AutoFW/local/lib/python2.7/site-packages/requests/api.py", line 112, in post
    return request('post', url, data=data, json=json, **kwargs)
  File "/home/fzyzgong/.virtualenvs/AutoFW/local/lib/python2.7/site-packages/requests/api.py", line 58, in request
    return session.request(method=method, url=url, **kwargs)
  File "/home/fzyzgong/.virtualenvs/AutoFW/local/lib/python2.7/site-packages/requests/sessions.py", line 494, in request
    prep = self.prepare_request(req)
  File "/home/fzyzgong/.virtualenvs/AutoFW/local/lib/python2.7/site-packages/requests/sessions.py", line 437, in prepare_request
    hooks=merge_hooks(request.hooks, self.hooks),
  File "/home/fzyzgong/.virtualenvs/AutoFW/local/lib/python2.7/site-packages/requests/models.py", line 306, in prepare
    self.prepare_headers(headers)
  File "/home/fzyzgong/.virtualenvs/AutoFW/local/lib/python2.7/site-packages/requests/models.py", line 440, in prepare_headers
    check_header_validity(header)
  File "/home/fzyzgong/.virtualenvs/AutoFW/local/lib/python2.7/site-packages/requests/utils.py", line 872, in check_header_validity
    "bytes, not %s" % (name, value, type(value)))
InvalidHeader: Value for header {appId: 1} must be of type str or bytes, not <type 'int'>


INFO 2018-04-20 18:35:29,769 views.py views execute_test_script 1245: 登录初始化-2018_4_20_18_23_32.py:PASS:[time_consuming:0.053972]{ response : 'resultCode: 0' }
